{
 "cells": [
  {
   "cell_type": "markdown",
   "metadata": {},
   "source": [
    "## Ejercios de kata 10"
   ]
  },
  {
   "cell_type": "code",
   "execution_count": 9,
   "metadata": {},
   "outputs": [
    {
     "ename": "SyntaxError",
     "evalue": "invalid syntax (489051447.py, line 1)",
     "output_type": "error",
     "traceback": [
      "\u001b[1;36m  Input \u001b[1;32mIn [9]\u001b[1;36m\u001b[0m\n\u001b[1;33m    $ python3 open.py\u001b[0m\n\u001b[1;37m    ^\u001b[0m\n\u001b[1;31mSyntaxError\u001b[0m\u001b[1;31m:\u001b[0m invalid syntax\n"
     ]
    }
   ],
   "source": [
    "$ python3 open.py\n",
    "Traceback (most recent call last):\n",
    "File \"/tmp/open.py\", line 5, in <module>\n",
    "main()\n",
    "File \"/tmp/open.py\", line 2, in main\n",
    "open(\"/path/to/mars.jpg\")\n",
    "FileNotFoundError: [Errno 2] No such file or directory: '/path/to/mars.jpg'"
   ]
  },
  {
   "cell_type": "code",
   "execution_count": 16,
   "metadata": {},
   "outputs": [
    {
     "name": "stdout",
     "output_type": "stream",
     "text": [
      "Couldn't find the config.txt file!\n"
     ]
    }
   ],
   "source": [
    "def main():\n",
    "    try:\n",
    "        configuration = open('config.txt')\n",
    "    except FileNotFoundError:\n",
    "        print(\"Couldn't find the config.txt file!\")\n",
    "\n",
    "\n",
    "if __name__ == '__main__':\n",
    "    main()"
   ]
  },
  {
   "cell_type": "code",
   "execution_count": 15,
   "metadata": {},
   "outputs": [],
   "source": [
    "def main():\n",
    "    try:\n",
    "        configuration = open('config.txt')\n",
    "    except FileNotFoundError:\n",
    "        print(\"Couldn't find the config.txt file!\")\n",
    "    except IsADirectoryError:\n",
    "        print(\"Found config.txt but it is a directory, couldn't read it\")"
   ]
  },
  {
   "cell_type": "code",
   "execution_count": 18,
   "metadata": {},
   "outputs": [],
   "source": [
    "def main():\n",
    "    try:\n",
    "        configuration = open('config.txt')\n",
    "    except FileNotFoundError:\n",
    "        print(\"Couldn't find the config.txt file!\")\n",
    "    except IsADirectoryError:\n",
    "        print(\"Found config.txt but it is a directory, couldn't read it\")\n",
    "    except (BlockingIOError, TimeoutError):\n",
    "        print(\"Filesystem under heavy load, can't complete reading configuration file\")"
   ]
  },
  {
   "cell_type": "code",
   "execution_count": 19,
   "metadata": {},
   "outputs": [
    {
     "ename": "SyntaxError",
     "evalue": "invalid syntax (1535621218.py, line 6)",
     "output_type": "error",
     "traceback": [
      "\u001b[1;36m  Input \u001b[1;32mIn [19]\u001b[1;36m\u001b[0m\n\u001b[1;33m    got a problem trying to read the file: [Errno 2] No such file or directory: 'mars.jpg'\u001b[0m\n\u001b[1;37m        ^\u001b[0m\n\u001b[1;31mSyntaxError\u001b[0m\u001b[1;31m:\u001b[0m invalid syntax\n"
     ]
    }
   ],
   "source": [
    ">>> try:\n",
    "...     open(\"mars.jpg\")\n",
    "... except FileNotFoundError as err:\n",
    "...     print(\"got a problem trying to read the file:\", err)\n",
    "...\n",
    "got a problem trying to read the file: [Errno 2] No such file or directory: 'mars.jpg'"
   ]
  },
  {
   "cell_type": "code",
   "execution_count": null,
   "metadata": {},
   "outputs": [],
   "source": [
    "$ python config.py\n",
    "Found config.txt but couldn't read it"
   ]
  },
  {
   "cell_type": "code",
   "execution_count": null,
   "metadata": {},
   "outputs": [],
   "source": [
    ">>> try:\n",
    "...     open(\"config.txt\")\n",
    "... except OSError as err:\n",
    "...     if err.errno == 2:\n",
    "...         print(\"Couldn't find the config.txt file!\")\n",
    "...     elif err.errno == 13:\n",
    "...         print(\"Found config.txt but couldn't read it\")\n",
    "...\n",
    "Couldn't find the config.txt file!"
   ]
  },
  {
   "cell_type": "markdown",
   "metadata": {},
   "source": [
    "## Genereacion de excepciones"
   ]
  },
  {
   "cell_type": "code",
   "execution_count": 1,
   "metadata": {},
   "outputs": [
    {
     "ename": "SyntaxError",
     "evalue": "EOL while scanning string literal (3569964609.py, line 9)",
     "output_type": "error",
     "traceback": [
      "\u001b[1;36m  Input \u001b[1;32mIn [1]\u001b[1;36m\u001b[0m\n\u001b[1;33m    Couldn't find the config.txt file!\u001b[0m\n\u001b[1;37m                                      ^\u001b[0m\n\u001b[1;31mSyntaxError\u001b[0m\u001b[1;31m:\u001b[0m EOL while scanning string literal\n"
     ]
    }
   ],
   "source": [
    ">>> try:\n",
    "...     open(\"config.txt\")\n",
    "... except OSError as err:\n",
    "...     if err.errno == 2:\n",
    "...         print(\"Couldn't find the config.txt file!\")\n",
    "...     elif err.errno == 13:\n",
    "...         print(\"Found config.txt but couldn't read it\")\n",
    "...\n",
    "Couldn't find the config.txt file!"
   ]
  },
  {
   "cell_type": "code",
   "execution_count": 2,
   "metadata": {},
   "outputs": [
    {
     "ename": "NameError",
     "evalue": "name 'water_left' is not defined",
     "output_type": "error",
     "traceback": [
      "\u001b[1;31m---------------------------------------------------------------------------\u001b[0m",
      "\u001b[1;31mNameError\u001b[0m                                 Traceback (most recent call last)",
      "\u001b[1;32mc:\\Users\\favio\\Desktop\\katasPropias\\Kata 10.ipynb Cell 11'\u001b[0m in \u001b[0;36m<module>\u001b[1;34m\u001b[0m\n\u001b[1;32m----> <a href='vscode-notebook-cell:/c%3A/Users/favio/Desktop/katasPropias/Kata%2010.ipynb#ch0000011?line=0'>1</a>\u001b[0m water_left(\u001b[39m5\u001b[39m, \u001b[39m100\u001b[39m, \u001b[39m2\u001b[39m)\n\u001b[0;32m      <a href='vscode-notebook-cell:/c%3A/Users/favio/Desktop/katasPropias/Kata%2010.ipynb#ch0000011?line=1'>2</a>\u001b[0m \u001b[39m'\u001b[39m\u001b[39mTotal water left after 2 days is: -10 liters\u001b[39m\u001b[39m'\u001b[39m\n",
      "\u001b[1;31mNameError\u001b[0m: name 'water_left' is not defined"
     ]
    }
   ],
   "source": [
    ">>> water_left(5, 100, 2)\n",
    "'Total water left after 2 days is: -10 liters'"
   ]
  },
  {
   "cell_type": "code",
   "execution_count": 4,
   "metadata": {},
   "outputs": [
    {
     "ename": "IndentationError",
     "evalue": "unexpected indent (1031860116.py, line 16)",
     "output_type": "error",
     "traceback": [
      "\u001b[1;36m  Input \u001b[1;32mIn [4]\u001b[1;36m\u001b[0m\n\u001b[1;33m    water_left(\"3\", \"200\", None)\u001b[0m\n\u001b[1;37m    ^\u001b[0m\n\u001b[1;31mIndentationError\u001b[0m\u001b[1;31m:\u001b[0m unexpected indent\n"
     ]
    }
   ],
   "source": [
    " water_left(\"3\", \"200\", None)\n",
    "Traceback (most recent call last):\n",
    "  File \"<stdin>\", line 1, in <module>\n",
    "  File \"<stdin>\", line 3, in water_left\n",
    "TypeError: can't multiply sequence by non-int of type 'NoneType'\n",
    "\n",
    "\n",
    "def water_left(astronauts, water_left, days_left):\n",
    "    for argument in [astronauts, water_left, days_left]:\n",
    "        try:\n",
    "            # If argument is an int, the following operation will work\n",
    "            argument / 10\n",
    "        except TypeError:\n",
    "            # TypError will be raised only if it isn't the right type \n",
    "            # Raise the same exception but with a better error message\n",
    "            raise TypeError(f\"All arguments must be of type int, but received: '{argument}'\")\n",
    "    daily_usage = astronauts * 11\n",
    "    total_usage = daily_usage * days_left\n",
    "    total_water_left = water_left - total_usage\n",
    "    if total_water_left < 0:\n",
    "        raise RuntimeError(f\"There is not enough water for {astronauts} astronauts after {days_left} days!\")\n",
    "    return f\"Total water left after {days_left} days is: {total_water_left} liters\"\n",
    "     water_left(\"3\", \"200\", None)\n",
    "Traceback (most recent call last):\n",
    "  File \"<stdin>\", line 5, in water_left\n",
    "TypeError: unsupported operand type(s) for /: 'str' and 'int'\n",
    "\n",
    "During handling of the preceding exception, another exception occurred:\n",
    "\n",
    "Traceback (most recent call last):\n",
    "  File \"<stdin>\", line 1, in <module>\n",
    "  File \"<stdin>\", line 9, in water_left\n",
    "TypeError: All arguments must be of type int, but received: '3"
   ]
  }
 ],
 "metadata": {
  "interpreter": {
   "hash": "d3dbcc44e2157b99ed3056c04be590c7bdcc9bcb82f5a0492b9e74f69acab332"
  },
  "kernelspec": {
   "display_name": "Python 3.9.5 64-bit",
   "language": "python",
   "name": "python3"
  },
  "language_info": {
   "codemirror_mode": {
    "name": "ipython",
    "version": 3
   },
   "file_extension": ".py",
   "mimetype": "text/x-python",
   "name": "python",
   "nbconvert_exporter": "python",
   "pygments_lexer": "ipython3",
   "version": "3.9.5"
  },
  "orig_nbformat": 4
 },
 "nbformat": 4,
 "nbformat_minor": 2
}
